asyncio - ERROR - Task exception was never retrieved
future: <Task finished name='Task-5043' coro=<TCPConnector._resolve_host() done, defined at /home/diego-moraes/.local/lib/python3.8/site-packages/aiohttp/connector.py:774> exception=gaierror(-2, 'Name or service not known')>
Traceback (most recent call last):
  File "/home/diego-moraes/.local/lib/python3.8/site-packages/aiohttp/connector.py", line 829, in _resolve_host
    addrs = await \
  File "/home/diego-moraes/.local/lib/python3.8/site-packages/aiohttp/resolver.py", line 29, in resolve
    infos = await self._loop.getaddrinfo(
  File "/usr/lib/python3.8/asyncio/base_events.py", line 825, in getaddrinfo
    return await self.run_in_executor(
  File "/usr/lib/python3.8/concurrent/futures/thread.py", line 57, in run
    result = self.fn(*self.args, **self.kwargs)
  File "/usr/lib/python3.8/socket.py", line 918, in getaddrinfo
    for res in _socket.getaddrinfo(host, port, family, type, proto, flags):
socket.gaierror: [Errno -2] Name or service not known
asyncio - ERROR - Task exception was never retrieved
future: <Task finished name='Task-5044' coro=<TCPConnector._resolve_host() done, defined at /home/diego-moraes/.local/lib/python3.8/site-packages/aiohttp/connector.py:774> exception=gaierror(-2, 'Name or service not known')>
Traceback (most recent call last):
  File "/home/diego-moraes/.local/lib/python3.8/site-packages/aiohttp/connector.py", line 829, in _resolve_host
    addrs = await \
  File "/home/diego-moraes/.local/lib/python3.8/site-packages/aiohttp/resolver.py", line 29, in resolve
    infos = await self._loop.getaddrinfo(
  File "/usr/lib/python3.8/asyncio/base_events.py", line 825, in getaddrinfo
    return await self.run_in_executor(
  File "/usr/lib/python3.8/concurrent/futures/thread.py", line 57, in run
    result = self.fn(*self.args, **self.kwargs)
  File "/usr/lib/python3.8/socket.py", line 918, in getaddrinfo
    for res in _socket.getaddrinfo(host, port, family, type, proto, flags):
socket.gaierror: [Errno -2] Name or service not known
asyncio - ERROR - Task exception was never retrieved
future: <Task finished name='Task-5046' coro=<TCPConnector._resolve_host() done, defined at /home/diego-moraes/.local/lib/python3.8/site-packages/aiohttp/connector.py:774> exception=gaierror(-2, 'Name or service not known')>
Traceback (most recent call last):
  File "/home/diego-moraes/.local/lib/python3.8/site-packages/aiohttp/connector.py", line 829, in _resolve_host
    addrs = await \
  File "/home/diego-moraes/.local/lib/python3.8/site-packages/aiohttp/resolver.py", line 29, in resolve
    infos = await self._loop.getaddrinfo(
  File "/usr/lib/python3.8/asyncio/base_events.py", line 825, in getaddrinfo
    return await self.run_in_executor(
  File "/usr/lib/python3.8/concurrent/futures/thread.py", line 57, in run
    result = self.fn(*self.args, **self.kwargs)
  File "/usr/lib/python3.8/socket.py", line 918, in getaddrinfo
    for res in _socket.getaddrinfo(host, port, family, type, proto, flags):
socket.gaierror: [Errno -2] Name or service not known
asyncio - ERROR - Task exception was never retrieved
future: <Task finished name='Task-5045' coro=<TCPConnector._resolve_host() done, defined at /home/diego-moraes/.local/lib/python3.8/site-packages/aiohttp/connector.py:774> exception=gaierror(-2, 'Name or service not known')>
Traceback (most recent call last):
  File "/home/diego-moraes/.local/lib/python3.8/site-packages/aiohttp/connector.py", line 829, in _resolve_host
    addrs = await \
  File "/home/diego-moraes/.local/lib/python3.8/site-packages/aiohttp/resolver.py", line 29, in resolve
    infos = await self._loop.getaddrinfo(
  File "/usr/lib/python3.8/asyncio/base_events.py", line 825, in getaddrinfo
    return await self.run_in_executor(
  File "/usr/lib/python3.8/concurrent/futures/thread.py", line 57, in run
    result = self.fn(*self.args, **self.kwargs)
  File "/usr/lib/python3.8/socket.py", line 918, in getaddrinfo
    for res in _socket.getaddrinfo(host, port, family, type, proto, flags):
socket.gaierror: [Errno -2] Name or service not known
asyncio - ERROR - Task exception was never retrieved
future: <Task finished name='Task-5048' coro=<TCPConnector._resolve_host() done, defined at /home/diego-moraes/.local/lib/python3.8/site-packages/aiohttp/connector.py:774> exception=gaierror(-2, 'Name or service not known')>
Traceback (most recent call last):
  File "/home/diego-moraes/.local/lib/python3.8/site-packages/aiohttp/connector.py", line 829, in _resolve_host
    addrs = await \
  File "/home/diego-moraes/.local/lib/python3.8/site-packages/aiohttp/resolver.py", line 29, in resolve
    infos = await self._loop.getaddrinfo(
  File "/usr/lib/python3.8/asyncio/base_events.py", line 825, in getaddrinfo
    return await self.run_in_executor(
  File "/usr/lib/python3.8/concurrent/futures/thread.py", line 57, in run
    result = self.fn(*self.args, **self.kwargs)
  File "/usr/lib/python3.8/socket.py", line 918, in getaddrinfo
    for res in _socket.getaddrinfo(host, port, family, type, proto, flags):
socket.gaierror: [Errno -2] Name or service not known
asyncio - ERROR - Task exception was never retrieved
future: <Task finished name='Task-5042' coro=<TCPConnector._resolve_host() done, defined at /home/diego-moraes/.local/lib/python3.8/site-packages/aiohttp/connector.py:774> exception=gaierror(-2, 'Name or service not known')>
Traceback (most recent call last):
  File "/home/diego-moraes/.local/lib/python3.8/site-packages/aiohttp/connector.py", line 829, in _resolve_host
    addrs = await \
  File "/home/diego-moraes/.local/lib/python3.8/site-packages/aiohttp/resolver.py", line 29, in resolve
    infos = await self._loop.getaddrinfo(
  File "/usr/lib/python3.8/asyncio/base_events.py", line 825, in getaddrinfo
    return await self.run_in_executor(
  File "/usr/lib/python3.8/concurrent/futures/thread.py", line 57, in run
    result = self.fn(*self.args, **self.kwargs)
  File "/usr/lib/python3.8/socket.py", line 918, in getaddrinfo
    for res in _socket.getaddrinfo(host, port, family, type, proto, flags):
socket.gaierror: [Errno -2] Name or service not known
asyncio - ERROR - Task exception was never retrieved
future: <Task finished name='Task-5004' coro=<TCPConnector._resolve_host() done, defined at /home/diego-moraes/.local/lib/python3.8/site-packages/aiohttp/connector.py:774> exception=gaierror(-3, 'Temporary failure in name resolution')>
Traceback (most recent call last):
  File "/home/diego-moraes/.local/lib/python3.8/site-packages/aiohttp/connector.py", line 829, in _resolve_host
    addrs = await \
  File "/home/diego-moraes/.local/lib/python3.8/site-packages/aiohttp/resolver.py", line 29, in resolve
    infos = await self._loop.getaddrinfo(
  File "/usr/lib/python3.8/asyncio/base_events.py", line 825, in getaddrinfo
    return await self.run_in_executor(
  File "/usr/lib/python3.8/concurrent/futures/thread.py", line 57, in run
    result = self.fn(*self.args, **self.kwargs)
  File "/usr/lib/python3.8/socket.py", line 918, in getaddrinfo
    for res in _socket.getaddrinfo(host, port, family, type, proto, flags):
socket.gaierror: [Errno -3] Temporary failure in name resolution
asyncio - ERROR - Task exception was never retrieved
future: <Task finished name='Task-5005' coro=<TCPConnector._resolve_host() done, defined at /home/diego-moraes/.local/lib/python3.8/site-packages/aiohttp/connector.py:774> exception=gaierror(-3, 'Temporary failure in name resolution')>
Traceback (most recent call last):
  File "/home/diego-moraes/.local/lib/python3.8/site-packages/aiohttp/connector.py", line 829, in _resolve_host
    addrs = await \
  File "/home/diego-moraes/.local/lib/python3.8/site-packages/aiohttp/resolver.py", line 29, in resolve
    infos = await self._loop.getaddrinfo(
  File "/usr/lib/python3.8/asyncio/base_events.py", line 825, in getaddrinfo
    return await self.run_in_executor(
  File "/usr/lib/python3.8/concurrent/futures/thread.py", line 57, in run
    result = self.fn(*self.args, **self.kwargs)
  File "/usr/lib/python3.8/socket.py", line 918, in getaddrinfo
    for res in _socket.getaddrinfo(host, port, family, type, proto, flags):
socket.gaierror: [Errno -3] Temporary failure in name resolution
asyncio - ERROR - Task exception was never retrieved
future: <Task finished name='Task-5008' coro=<TCPConnector._resolve_host() done, defined at /home/diego-moraes/.local/lib/python3.8/site-packages/aiohttp/connector.py:774> exception=gaierror(-3, 'Temporary failure in name resolution')>
Traceback (most recent call last):
  File "/home/diego-moraes/.local/lib/python3.8/site-packages/aiohttp/connector.py", line 829, in _resolve_host
    addrs = await \
  File "/home/diego-moraes/.local/lib/python3.8/site-packages/aiohttp/resolver.py", line 29, in resolve
    infos = await self._loop.getaddrinfo(
  File "/usr/lib/python3.8/asyncio/base_events.py", line 825, in getaddrinfo
    return await self.run_in_executor(
  File "/usr/lib/python3.8/concurrent/futures/thread.py", line 57, in run
    result = self.fn(*self.args, **self.kwargs)
  File "/usr/lib/python3.8/socket.py", line 918, in getaddrinfo
    for res in _socket.getaddrinfo(host, port, family, type, proto, flags):
socket.gaierror: [Errno -3] Temporary failure in name resolution
asyncio - ERROR - Task exception was never retrieved
future: <Task finished name='Task-5009' coro=<TCPConnector._resolve_host() done, defined at /home/diego-moraes/.local/lib/python3.8/site-packages/aiohttp/connector.py:774> exception=gaierror(-3, 'Temporary failure in name resolution')>
Traceback (most recent call last):
  File "/home/diego-moraes/.local/lib/python3.8/site-packages/aiohttp/connector.py", line 829, in _resolve_host
    addrs = await \
  File "/home/diego-moraes/.local/lib/python3.8/site-packages/aiohttp/resolver.py", line 29, in resolve
    infos = await self._loop.getaddrinfo(
  File "/usr/lib/python3.8/asyncio/base_events.py", line 825, in getaddrinfo
    return await self.run_in_executor(
  File "/usr/lib/python3.8/concurrent/futures/thread.py", line 57, in run
    result = self.fn(*self.args, **self.kwargs)
  File "/usr/lib/python3.8/socket.py", line 918, in getaddrinfo
    for res in _socket.getaddrinfo(host, port, family, type, proto, flags):
socket.gaierror: [Errno -3] Temporary failure in name resolution
asyncio - ERROR - Task exception was never retrieved
future: <Task finished name='Task-5002' coro=<TCPConnector._resolve_host() done, defined at /home/diego-moraes/.local/lib/python3.8/site-packages/aiohttp/connector.py:774> exception=gaierror(-2, 'Name or service not known')>
Traceback (most recent call last):
  File "/home/diego-moraes/.local/lib/python3.8/site-packages/aiohttp/connector.py", line 829, in _resolve_host
    addrs = await \
  File "/home/diego-moraes/.local/lib/python3.8/site-packages/aiohttp/resolver.py", line 29, in resolve
    infos = await self._loop.getaddrinfo(
  File "/usr/lib/python3.8/asyncio/base_events.py", line 825, in getaddrinfo
    return await self.run_in_executor(
  File "/usr/lib/python3.8/concurrent/futures/thread.py", line 57, in run
    result = self.fn(*self.args, **self.kwargs)
  File "/usr/lib/python3.8/socket.py", line 918, in getaddrinfo
    for res in _socket.getaddrinfo(host, port, family, type, proto, flags):
socket.gaierror: [Errno -2] Name or service not known
asyncio - ERROR - Task exception was never retrieved
future: <Task finished name='Task-5057' coro=<TCPConnector._resolve_host() done, defined at /home/diego-moraes/.local/lib/python3.8/site-packages/aiohttp/connector.py:774> exception=gaierror(-2, 'Name or service not known')>
Traceback (most recent call last):
  File "/home/diego-moraes/.local/lib/python3.8/site-packages/aiohttp/connector.py", line 829, in _resolve_host
    addrs = await \
  File "/home/diego-moraes/.local/lib/python3.8/site-packages/aiohttp/resolver.py", line 29, in resolve
    infos = await self._loop.getaddrinfo(
  File "/usr/lib/python3.8/asyncio/base_events.py", line 825, in getaddrinfo
    return await self.run_in_executor(
  File "/usr/lib/python3.8/concurrent/futures/thread.py", line 57, in run
    result = self.fn(*self.args, **self.kwargs)
  File "/usr/lib/python3.8/socket.py", line 918, in getaddrinfo
    for res in _socket.getaddrinfo(host, port, family, type, proto, flags):
socket.gaierror: [Errno -2] Name or service not known
asyncio - ERROR - Task exception was never retrieved
future: <Task finished name='Task-5056' coro=<TCPConnector._resolve_host() done, defined at /home/diego-moraes/.local/lib/python3.8/site-packages/aiohttp/connector.py:774> exception=gaierror(-2, 'Name or service not known')>
Traceback (most recent call last):
  File "/home/diego-moraes/.local/lib/python3.8/site-packages/aiohttp/connector.py", line 829, in _resolve_host
    addrs = await \
  File "/home/diego-moraes/.local/lib/python3.8/site-packages/aiohttp/resolver.py", line 29, in resolve
    infos = await self._loop.getaddrinfo(
  File "/usr/lib/python3.8/asyncio/base_events.py", line 825, in getaddrinfo
    return await self.run_in_executor(
  File "/usr/lib/python3.8/concurrent/futures/thread.py", line 57, in run
    result = self.fn(*self.args, **self.kwargs)
  File "/usr/lib/python3.8/socket.py", line 918, in getaddrinfo
    for res in _socket.getaddrinfo(host, port, family, type, proto, flags):
socket.gaierror: [Errno -2] Name or service not known
asyncio - ERROR - Task exception was never retrieved
future: <Task finished name='Task-5034' coro=<TCPConnector._resolve_host() done, defined at /home/diego-moraes/.local/lib/python3.8/site-packages/aiohttp/connector.py:774> exception=gaierror(-3, 'Temporary failure in name resolution')>
Traceback (most recent call last):
  File "/home/diego-moraes/.local/lib/python3.8/site-packages/aiohttp/connector.py", line 829, in _resolve_host
    addrs = await \
  File "/home/diego-moraes/.local/lib/python3.8/site-packages/aiohttp/resolver.py", line 29, in resolve
    infos = await self._loop.getaddrinfo(
  File "/usr/lib/python3.8/asyncio/base_events.py", line 825, in getaddrinfo
    return await self.run_in_executor(
  File "/usr/lib/python3.8/concurrent/futures/thread.py", line 57, in run
    result = self.fn(*self.args, **self.kwargs)
  File "/usr/lib/python3.8/socket.py", line 918, in getaddrinfo
    for res in _socket.getaddrinfo(host, port, family, type, proto, flags):
socket.gaierror: [Errno -3] Temporary failure in name resolution
asyncio - ERROR - Task exception was never retrieved
future: <Task finished name='Task-5052' coro=<TCPConnector._resolve_host() done, defined at /home/diego-moraes/.local/lib/python3.8/site-packages/aiohttp/connector.py:774> exception=gaierror(-3, 'Temporary failure in name resolution')>
Traceback (most recent call last):
  File "/home/diego-moraes/.local/lib/python3.8/site-packages/aiohttp/connector.py", line 829, in _resolve_host
    addrs = await \
  File "/home/diego-moraes/.local/lib/python3.8/site-packages/aiohttp/resolver.py", line 29, in resolve
    infos = await self._loop.getaddrinfo(
  File "/usr/lib/python3.8/asyncio/base_events.py", line 825, in getaddrinfo
    return await self.run_in_executor(
  File "/usr/lib/python3.8/concurrent/futures/thread.py", line 57, in run
    result = self.fn(*self.args, **self.kwargs)
  File "/usr/lib/python3.8/socket.py", line 918, in getaddrinfo
    for res in _socket.getaddrinfo(host, port, family, type, proto, flags):
socket.gaierror: [Errno -3] Temporary failure in name resolution
asyncio - ERROR - Task exception was never retrieved
future: <Task finished name='Task-5049' coro=<TCPConnector._resolve_host() done, defined at /home/diego-moraes/.local/lib/python3.8/site-packages/aiohttp/connector.py:774> exception=gaierror(-3, 'Temporary failure in name resolution')>
Traceback (most recent call last):
  File "/home/diego-moraes/.local/lib/python3.8/site-packages/aiohttp/connector.py", line 829, in _resolve_host
    addrs = await \
  File "/home/diego-moraes/.local/lib/python3.8/site-packages/aiohttp/resolver.py", line 29, in resolve
    infos = await self._loop.getaddrinfo(
  File "/usr/lib/python3.8/asyncio/base_events.py", line 825, in getaddrinfo
    return await self.run_in_executor(
  File "/usr/lib/python3.8/concurrent/futures/thread.py", line 57, in run
    result = self.fn(*self.args, **self.kwargs)
  File "/usr/lib/python3.8/socket.py", line 918, in getaddrinfo
    for res in _socket.getaddrinfo(host, port, family, type, proto, flags):
socket.gaierror: [Errno -3] Temporary failure in name resolution
asyncio - ERROR - Task exception was never retrieved
future: <Task finished name='Task-5054' coro=<TCPConnector._resolve_host() done, defined at /home/diego-moraes/.local/lib/python3.8/site-packages/aiohttp/connector.py:774> exception=gaierror(-3, 'Temporary failure in name resolution')>
Traceback (most recent call last):
  File "/home/diego-moraes/.local/lib/python3.8/site-packages/aiohttp/connector.py", line 829, in _resolve_host
    addrs = await \
  File "/home/diego-moraes/.local/lib/python3.8/site-packages/aiohttp/resolver.py", line 29, in resolve
    infos = await self._loop.getaddrinfo(
  File "/usr/lib/python3.8/asyncio/base_events.py", line 825, in getaddrinfo
    return await self.run_in_executor(
  File "/usr/lib/python3.8/concurrent/futures/thread.py", line 57, in run
    result = self.fn(*self.args, **self.kwargs)
  File "/usr/lib/python3.8/socket.py", line 918, in getaddrinfo
    for res in _socket.getaddrinfo(host, port, family, type, proto, flags):
socket.gaierror: [Errno -3] Temporary failure in name resolution
asyncio - ERROR - Task exception was never retrieved
future: <Task finished name='Task-5053' coro=<TCPConnector._resolve_host() done, defined at /home/diego-moraes/.local/lib/python3.8/site-packages/aiohttp/connector.py:774> exception=gaierror(-3, 'Temporary failure in name resolution')>
Traceback (most recent call last):
  File "/home/diego-moraes/.local/lib/python3.8/site-packages/aiohttp/connector.py", line 829, in _resolve_host
    addrs = await \
  File "/home/diego-moraes/.local/lib/python3.8/site-packages/aiohttp/resolver.py", line 29, in resolve
    infos = await self._loop.getaddrinfo(
  File "/usr/lib/python3.8/asyncio/base_events.py", line 825, in getaddrinfo
    return await self.run_in_executor(
  File "/usr/lib/python3.8/concurrent/futures/thread.py", line 57, in run
    result = self.fn(*self.args, **self.kwargs)
  File "/usr/lib/python3.8/socket.py", line 918, in getaddrinfo
    for res in _socket.getaddrinfo(host, port, family, type, proto, flags):
socket.gaierror: [Errno -3] Temporary failure in name resolution
asyncio - ERROR - Task exception was never retrieved
future: <Task finished name='Task-5050' coro=<TCPConnector._resolve_host() done, defined at /home/diego-moraes/.local/lib/python3.8/site-packages/aiohttp/connector.py:774> exception=gaierror(-3, 'Temporary failure in name resolution')>
Traceback (most recent call last):
  File "/home/diego-moraes/.local/lib/python3.8/site-packages/aiohttp/connector.py", line 829, in _resolve_host
    addrs = await \
  File "/home/diego-moraes/.local/lib/python3.8/site-packages/aiohttp/resolver.py", line 29, in resolve
    infos = await self._loop.getaddrinfo(
  File "/usr/lib/python3.8/asyncio/base_events.py", line 825, in getaddrinfo
    return await self.run_in_executor(
  File "/usr/lib/python3.8/concurrent/futures/thread.py", line 57, in run
    result = self.fn(*self.args, **self.kwargs)
  File "/usr/lib/python3.8/socket.py", line 918, in getaddrinfo
    for res in _socket.getaddrinfo(host, port, family, type, proto, flags):
socket.gaierror: [Errno -3] Temporary failure in name resolution
asyncio - ERROR - Task exception was never retrieved
future: <Task finished name='Task-5051' coro=<TCPConnector._resolve_host() done, defined at /home/diego-moraes/.local/lib/python3.8/site-packages/aiohttp/connector.py:774> exception=gaierror(-3, 'Temporary failure in name resolution')>
Traceback (most recent call last):
  File "/home/diego-moraes/.local/lib/python3.8/site-packages/aiohttp/connector.py", line 829, in _resolve_host
    addrs = await \
  File "/home/diego-moraes/.local/lib/python3.8/site-packages/aiohttp/resolver.py", line 29, in resolve
    infos = await self._loop.getaddrinfo(
  File "/usr/lib/python3.8/asyncio/base_events.py", line 825, in getaddrinfo
    return await self.run_in_executor(
  File "/usr/lib/python3.8/concurrent/futures/thread.py", line 57, in run
    result = self.fn(*self.args, **self.kwargs)
  File "/usr/lib/python3.8/socket.py", line 918, in getaddrinfo
    for res in _socket.getaddrinfo(host, port, family, type, proto, flags):
socket.gaierror: [Errno -3] Temporary failure in name resolution
asyncio - ERROR - Task exception was never retrieved
future: <Task finished name='Task-5063' coro=<TCPConnector._resolve_host() done, defined at /home/diego-moraes/.local/lib/python3.8/site-packages/aiohttp/connector.py:774> exception=gaierror(-2, 'Name or service not known')>
Traceback (most recent call last):
  File "/home/diego-moraes/.local/lib/python3.8/site-packages/aiohttp/connector.py", line 829, in _resolve_host
    addrs = await \
  File "/home/diego-moraes/.local/lib/python3.8/site-packages/aiohttp/resolver.py", line 29, in resolve
    infos = await self._loop.getaddrinfo(
  File "/usr/lib/python3.8/asyncio/base_events.py", line 825, in getaddrinfo
    return await self.run_in_executor(
  File "/usr/lib/python3.8/concurrent/futures/thread.py", line 57, in run
    result = self.fn(*self.args, **self.kwargs)
  File "/usr/lib/python3.8/socket.py", line 918, in getaddrinfo
    for res in _socket.getaddrinfo(host, port, family, type, proto, flags):
socket.gaierror: [Errno -2] Name or service not known
asyncio - ERROR - Task exception was never retrieved
future: <Task finished name='Task-5065' coro=<TCPConnector._resolve_host() done, defined at /home/diego-moraes/.local/lib/python3.8/site-packages/aiohttp/connector.py:774> exception=gaierror(-2, 'Name or service not known')>
Traceback (most recent call last):
  File "/home/diego-moraes/.local/lib/python3.8/site-packages/aiohttp/connector.py", line 829, in _resolve_host
    addrs = await \
  File "/home/diego-moraes/.local/lib/python3.8/site-packages/aiohttp/resolver.py", line 29, in resolve
    infos = await self._loop.getaddrinfo(
  File "/usr/lib/python3.8/asyncio/base_events.py", line 825, in getaddrinfo
    return await self.run_in_executor(
  File "/usr/lib/python3.8/concurrent/futures/thread.py", line 57, in run
    result = self.fn(*self.args, **self.kwargs)
  File "/usr/lib/python3.8/socket.py", line 918, in getaddrinfo
    for res in _socket.getaddrinfo(host, port, family, type, proto, flags):
socket.gaierror: [Errno -2] Name or service not known
asyncio - ERROR - Task exception was never retrieved
future: <Task finished name='Task-5211' coro=<TCPConnector._resolve_host() done, defined at /home/diego-moraes/.local/lib/python3.8/site-packages/aiohttp/connector.py:774> exception=gaierror(-2, 'Name or service not known')>
Traceback (most recent call last):
  File "/home/diego-moraes/.local/lib/python3.8/site-packages/aiohttp/connector.py", line 815, in _resolve_host
    await event.wait()
  File "/home/diego-moraes/.local/lib/python3.8/site-packages/aiohttp/locks.py", line 37, in wait
    raise self._exc
  File "/home/diego-moraes/.local/lib/python3.8/site-packages/aiohttp/connector.py", line 829, in _resolve_host
    addrs = await \
  File "/home/diego-moraes/.local/lib/python3.8/site-packages/aiohttp/resolver.py", line 29, in resolve
    infos = await self._loop.getaddrinfo(
  File "/usr/lib/python3.8/asyncio/base_events.py", line 825, in getaddrinfo
    return await self.run_in_executor(
  File "/usr/lib/python3.8/concurrent/futures/thread.py", line 57, in run
    result = self.fn(*self.args, **self.kwargs)
  File "/usr/lib/python3.8/socket.py", line 918, in getaddrinfo
    for res in _socket.getaddrinfo(host, port, family, type, proto, flags):
socket.gaierror: [Errno -2] Name or service not known
asyncio - ERROR - Task exception was never retrieved
future: <Task finished name='Task-5066' coro=<TCPConnector._resolve_host() done, defined at /home/diego-moraes/.local/lib/python3.8/site-packages/aiohttp/connector.py:774> exception=gaierror(-2, 'Name or service not known')>
Traceback (most recent call last):
  File "/home/diego-moraes/.local/lib/python3.8/site-packages/aiohttp/connector.py", line 829, in _resolve_host
    addrs = await \
  File "/home/diego-moraes/.local/lib/python3.8/site-packages/aiohttp/resolver.py", line 29, in resolve
    infos = await self._loop.getaddrinfo(
  File "/usr/lib/python3.8/asyncio/base_events.py", line 825, in getaddrinfo
    return await self.run_in_executor(
  File "/usr/lib/python3.8/concurrent/futures/thread.py", line 57, in run
    result = self.fn(*self.args, **self.kwargs)
  File "/usr/lib/python3.8/socket.py", line 918, in getaddrinfo
    for res in _socket.getaddrinfo(host, port, family, type, proto, flags):
socket.gaierror: [Errno -2] Name or service not known
asyncio - ERROR - Task exception was never retrieved
future: <Task finished name='Task-5068' coro=<TCPConnector._resolve_host() done, defined at /home/diego-moraes/.local/lib/python3.8/site-packages/aiohttp/connector.py:774> exception=gaierror(-2, 'Name or service not known')>
Traceback (most recent call last):
  File "/home/diego-moraes/.local/lib/python3.8/site-packages/aiohttp/connector.py", line 829, in _resolve_host
    addrs = await \
  File "/home/diego-moraes/.local/lib/python3.8/site-packages/aiohttp/resolver.py", line 29, in resolve
    infos = await self._loop.getaddrinfo(
  File "/usr/lib/python3.8/asyncio/base_events.py", line 825, in getaddrinfo
    return await self.run_in_executor(
  File "/usr/lib/python3.8/concurrent/futures/thread.py", line 57, in run
    result = self.fn(*self.args, **self.kwargs)
  File "/usr/lib/python3.8/socket.py", line 918, in getaddrinfo
    for res in _socket.getaddrinfo(host, port, family, type, proto, flags):
socket.gaierror: [Errno -2] Name or service not known
asyncio - ERROR - Task exception was never retrieved
future: <Task finished name='Task-5069' coro=<TCPConnector._resolve_host() done, defined at /home/diego-moraes/.local/lib/python3.8/site-packages/aiohttp/connector.py:774> exception=gaierror(-5, 'No address associated with hostname')>
Traceback (most recent call last):
  File "/home/diego-moraes/.local/lib/python3.8/site-packages/aiohttp/connector.py", line 829, in _resolve_host
    addrs = await \
  File "/home/diego-moraes/.local/lib/python3.8/site-packages/aiohttp/resolver.py", line 29, in resolve
    infos = await self._loop.getaddrinfo(
  File "/usr/lib/python3.8/asyncio/base_events.py", line 825, in getaddrinfo
    return await self.run_in_executor(
  File "/usr/lib/python3.8/concurrent/futures/thread.py", line 57, in run
    result = self.fn(*self.args, **self.kwargs)
  File "/usr/lib/python3.8/socket.py", line 918, in getaddrinfo
    for res in _socket.getaddrinfo(host, port, family, type, proto, flags):
socket.gaierror: [Errno -5] No address associated with hostname
asyncio - ERROR - Task exception was never retrieved
future: <Task finished name='Task-5067' coro=<TCPConnector._resolve_host() done, defined at /home/diego-moraes/.local/lib/python3.8/site-packages/aiohttp/connector.py:774> exception=gaierror(-2, 'Name or service not known')>
Traceback (most recent call last):
  File "/home/diego-moraes/.local/lib/python3.8/site-packages/aiohttp/connector.py", line 829, in _resolve_host
    addrs = await \
  File "/home/diego-moraes/.local/lib/python3.8/site-packages/aiohttp/resolver.py", line 29, in resolve
    infos = await self._loop.getaddrinfo(
  File "/usr/lib/python3.8/asyncio/base_events.py", line 825, in getaddrinfo
    return await self.run_in_executor(
  File "/usr/lib/python3.8/concurrent/futures/thread.py", line 57, in run
    result = self.fn(*self.args, **self.kwargs)
  File "/usr/lib/python3.8/socket.py", line 918, in getaddrinfo
    for res in _socket.getaddrinfo(host, port, family, type, proto, flags):
socket.gaierror: [Errno -2] Name or service not known
asyncio - ERROR - Task exception was never retrieved
future: <Task finished name='Task-5072' coro=<TCPConnector._resolve_host() done, defined at /home/diego-moraes/.local/lib/python3.8/site-packages/aiohttp/connector.py:774> exception=gaierror(-2, 'Name or service not known')>
Traceback (most recent call last):
  File "/home/diego-moraes/.local/lib/python3.8/site-packages/aiohttp/connector.py", line 829, in _resolve_host
    addrs = await \
  File "/home/diego-moraes/.local/lib/python3.8/site-packages/aiohttp/resolver.py", line 29, in resolve
    infos = await self._loop.getaddrinfo(
  File "/usr/lib/python3.8/asyncio/base_events.py", line 825, in getaddrinfo
    return await self.run_in_executor(
  File "/usr/lib/python3.8/concurrent/futures/thread.py", line 57, in run
    result = self.fn(*self.args, **self.kwargs)
  File "/usr/lib/python3.8/socket.py", line 918, in getaddrinfo
    for res in _socket.getaddrinfo(host, port, family, type, proto, flags):
socket.gaierror: [Errno -2] Name or service not known
asyncio - ERROR - Task exception was never retrieved
future: <Task finished name='Task-5070' coro=<TCPConnector._resolve_host() done, defined at /home/diego-moraes/.local/lib/python3.8/site-packages/aiohttp/connector.py:774> exception=gaierror(-2, 'Name or service not known')>
Traceback (most recent call last):
  File "/home/diego-moraes/.local/lib/python3.8/site-packages/aiohttp/connector.py", line 829, in _resolve_host
    addrs = await \
  File "/home/diego-moraes/.local/lib/python3.8/site-packages/aiohttp/resolver.py", line 29, in resolve
    infos = await self._loop.getaddrinfo(
  File "/usr/lib/python3.8/asyncio/base_events.py", line 825, in getaddrinfo
    return await self.run_in_executor(
  File "/usr/lib/python3.8/concurrent/futures/thread.py", line 57, in run
    result = self.fn(*self.args, **self.kwargs)
  File "/usr/lib/python3.8/socket.py", line 918, in getaddrinfo
    for res in _socket.getaddrinfo(host, port, family, type, proto, flags):
socket.gaierror: [Errno -2] Name or service not known
asyncio - ERROR - Task exception was never retrieved
future: <Task finished name='Task-5071' coro=<TCPConnector._resolve_host() done, defined at /home/diego-moraes/.local/lib/python3.8/site-packages/aiohttp/connector.py:774> exception=gaierror(-2, 'Name or service not known')>
Traceback (most recent call last):
  File "/home/diego-moraes/.local/lib/python3.8/site-packages/aiohttp/connector.py", line 829, in _resolve_host
    addrs = await \
  File "/home/diego-moraes/.local/lib/python3.8/site-packages/aiohttp/resolver.py", line 29, in resolve
    infos = await self._loop.getaddrinfo(
  File "/usr/lib/python3.8/asyncio/base_events.py", line 825, in getaddrinfo
    return await self.run_in_executor(
  File "/usr/lib/python3.8/concurrent/futures/thread.py", line 57, in run
    result = self.fn(*self.args, **self.kwargs)
  File "/usr/lib/python3.8/socket.py", line 918, in getaddrinfo
    for res in _socket.getaddrinfo(host, port, family, type, proto, flags):
socket.gaierror: [Errno -2] Name or service not known
asyncio - ERROR - Task exception was never retrieved
future: <Task finished name='Task-5074' coro=<TCPConnector._resolve_host() done, defined at /home/diego-moraes/.local/lib/python3.8/site-packages/aiohttp/connector.py:774> exception=gaierror(-2, 'Name or service not known')>
Traceback (most recent call last):
  File "/home/diego-moraes/.local/lib/python3.8/site-packages/aiohttp/connector.py", line 829, in _resolve_host
    addrs = await \
  File "/home/diego-moraes/.local/lib/python3.8/site-packages/aiohttp/resolver.py", line 29, in resolve
    infos = await self._loop.getaddrinfo(
  File "/usr/lib/python3.8/asyncio/base_events.py", line 825, in getaddrinfo
    return await self.run_in_executor(
  File "/usr/lib/python3.8/concurrent/futures/thread.py", line 57, in run
    result = self.fn(*self.args, **self.kwargs)
  File "/usr/lib/python3.8/socket.py", line 918, in getaddrinfo
    for res in _socket.getaddrinfo(host, port, family, type, proto, flags):
socket.gaierror: [Errno -2] Name or service not known
asyncio - ERROR - Task exception was never retrieved
future: <Task finished name='Task-5073' coro=<TCPConnector._resolve_host() done, defined at /home/diego-moraes/.local/lib/python3.8/site-packages/aiohttp/connector.py:774> exception=gaierror(-2, 'Name or service not known')>
Traceback (most recent call last):
  File "/home/diego-moraes/.local/lib/python3.8/site-packages/aiohttp/connector.py", line 829, in _resolve_host
    addrs = await \
  File "/home/diego-moraes/.local/lib/python3.8/site-packages/aiohttp/resolver.py", line 29, in resolve
    infos = await self._loop.getaddrinfo(
  File "/usr/lib/python3.8/asyncio/base_events.py", line 825, in getaddrinfo
    return await self.run_in_executor(
  File "/usr/lib/python3.8/concurrent/futures/thread.py", line 57, in run
    result = self.fn(*self.args, **self.kwargs)
  File "/usr/lib/python3.8/socket.py", line 918, in getaddrinfo
    for res in _socket.getaddrinfo(host, port, family, type, proto, flags):
socket.gaierror: [Errno -2] Name or service not known
asyncio - ERROR - Task exception was never retrieved
future: <Task finished name='Task-5077' coro=<TCPConnector._resolve_host() done, defined at /home/diego-moraes/.local/lib/python3.8/site-packages/aiohttp/connector.py:774> exception=gaierror(-2, 'Name or service not known')>
Traceback (most recent call last):
  File "/home/diego-moraes/.local/lib/python3.8/site-packages/aiohttp/connector.py", line 829, in _resolve_host
    addrs = await \
  File "/home/diego-moraes/.local/lib/python3.8/site-packages/aiohttp/resolver.py", line 29, in resolve
    infos = await self._loop.getaddrinfo(
  File "/usr/lib/python3.8/asyncio/base_events.py", line 825, in getaddrinfo
    return await self.run_in_executor(
  File "/usr/lib/python3.8/concurrent/futures/thread.py", line 57, in run
    result = self.fn(*self.args, **self.kwargs)
  File "/usr/lib/python3.8/socket.py", line 918, in getaddrinfo
    for res in _socket.getaddrinfo(host, port, family, type, proto, flags):
socket.gaierror: [Errno -2] Name or service not known
asyncio - ERROR - Task exception was never retrieved
future: <Task finished name='Task-5075' coro=<TCPConnector._resolve_host() done, defined at /home/diego-moraes/.local/lib/python3.8/site-packages/aiohttp/connector.py:774> exception=gaierror(-2, 'Name or service not known')>
Traceback (most recent call last):
  File "/home/diego-moraes/.local/lib/python3.8/site-packages/aiohttp/connector.py", line 829, in _resolve_host
    addrs = await \
  File "/home/diego-moraes/.local/lib/python3.8/site-packages/aiohttp/resolver.py", line 29, in resolve
    infos = await self._loop.getaddrinfo(
  File "/usr/lib/python3.8/asyncio/base_events.py", line 825, in getaddrinfo
    return await self.run_in_executor(
  File "/usr/lib/python3.8/concurrent/futures/thread.py", line 57, in run
    result = self.fn(*self.args, **self.kwargs)
  File "/usr/lib/python3.8/socket.py", line 918, in getaddrinfo
    for res in _socket.getaddrinfo(host, port, family, type, proto, flags):
socket.gaierror: [Errno -2] Name or service not known
asyncio - ERROR - Task exception was never retrieved
future: <Task finished name='Task-5055' coro=<TCPConnector._resolve_host() done, defined at /home/diego-moraes/.local/lib/python3.8/site-packages/aiohttp/connector.py:774> exception=gaierror(-3, 'Temporary failure in name resolution')>
Traceback (most recent call last):
  File "/home/diego-moraes/.local/lib/python3.8/site-packages/aiohttp/connector.py", line 829, in _resolve_host
    addrs = await \
  File "/home/diego-moraes/.local/lib/python3.8/site-packages/aiohttp/resolver.py", line 29, in resolve
    infos = await self._loop.getaddrinfo(
  File "/usr/lib/python3.8/asyncio/base_events.py", line 825, in getaddrinfo
    return await self.run_in_executor(
  File "/usr/lib/python3.8/concurrent/futures/thread.py", line 57, in run
    result = self.fn(*self.args, **self.kwargs)
  File "/usr/lib/python3.8/socket.py", line 918, in getaddrinfo
    for res in _socket.getaddrinfo(host, port, family, type, proto, flags):
socket.gaierror: [Errno -3] Temporary failure in name resolution
asyncio - ERROR - Task exception was never retrieved
future: <Task finished name='Task-5058' coro=<TCPConnector._resolve_host() done, defined at /home/diego-moraes/.local/lib/python3.8/site-packages/aiohttp/connector.py:774> exception=gaierror(-2, 'Name or service not known')>
Traceback (most recent call last):
  File "/home/diego-moraes/.local/lib/python3.8/site-packages/aiohttp/connector.py", line 829, in _resolve_host
    addrs = await \
  File "/home/diego-moraes/.local/lib/python3.8/site-packages/aiohttp/resolver.py", line 29, in resolve
    infos = await self._loop.getaddrinfo(
  File "/usr/lib/python3.8/asyncio/base_events.py", line 825, in getaddrinfo
    return await self.run_in_executor(
  File "/usr/lib/python3.8/concurrent/futures/thread.py", line 57, in run
    result = self.fn(*self.args, **self.kwargs)
  File "/usr/lib/python3.8/socket.py", line 918, in getaddrinfo
    for res in _socket.getaddrinfo(host, port, family, type, proto, flags):
socket.gaierror: [Errno -2] Name or service not known
asyncio - ERROR - Task exception was never retrieved
future: <Task finished name='Task-5060' coro=<TCPConnector._resolve_host() done, defined at /home/diego-moraes/.local/lib/python3.8/site-packages/aiohttp/connector.py:774> exception=gaierror(-2, 'Name or service not known')>
Traceback (most recent call last):
  File "/home/diego-moraes/.local/lib/python3.8/site-packages/aiohttp/connector.py", line 829, in _resolve_host
    addrs = await \
  File "/home/diego-moraes/.local/lib/python3.8/site-packages/aiohttp/resolver.py", line 29, in resolve
    infos = await self._loop.getaddrinfo(
  File "/usr/lib/python3.8/asyncio/base_events.py", line 825, in getaddrinfo
    return await self.run_in_executor(
  File "/usr/lib/python3.8/concurrent/futures/thread.py", line 57, in run
    result = self.fn(*self.args, **self.kwargs)
  File "/usr/lib/python3.8/socket.py", line 918, in getaddrinfo
    for res in _socket.getaddrinfo(host, port, family, type, proto, flags):
socket.gaierror: [Errno -2] Name or service not known
asyncio - ERROR - Task exception was never retrieved
future: <Task finished name='Task-5084' coro=<TCPConnector._resolve_host() done, defined at /home/diego-moraes/.local/lib/python3.8/site-packages/aiohttp/connector.py:774> exception=gaierror(-2, 'Name or service not known')>
Traceback (most recent call last):
  File "/home/diego-moraes/.local/lib/python3.8/site-packages/aiohttp/connector.py", line 829, in _resolve_host
    addrs = await \
  File "/home/diego-moraes/.local/lib/python3.8/site-packages/aiohttp/resolver.py", line 29, in resolve
    infos = await self._loop.getaddrinfo(
  File "/usr/lib/python3.8/asyncio/base_events.py", line 825, in getaddrinfo
    return await self.run_in_executor(
  File "/usr/lib/python3.8/concurrent/futures/thread.py", line 57, in run
    result = self.fn(*self.args, **self.kwargs)
  File "/usr/lib/python3.8/socket.py", line 918, in getaddrinfo
    for res in _socket.getaddrinfo(host, port, family, type, proto, flags):
socket.gaierror: [Errno -2] Name or service not known
asyncio - ERROR - Task exception was never retrieved
future: <Task finished name='Task-5062' coro=<TCPConnector._resolve_host() done, defined at /home/diego-moraes/.local/lib/python3.8/site-packages/aiohttp/connector.py:774> exception=gaierror(-3, 'Temporary failure in name resolution')>
Traceback (most recent call last):
  File "/home/diego-moraes/.local/lib/python3.8/site-packages/aiohttp/connector.py", line 829, in _resolve_host
    addrs = await \
  File "/home/diego-moraes/.local/lib/python3.8/site-packages/aiohttp/resolver.py", line 29, in resolve
    infos = await self._loop.getaddrinfo(
  File "/usr/lib/python3.8/asyncio/base_events.py", line 825, in getaddrinfo
    return await self.run_in_executor(
  File "/usr/lib/python3.8/concurrent/futures/thread.py", line 57, in run
    result = self.fn(*self.args, **self.kwargs)
  File "/usr/lib/python3.8/socket.py", line 918, in getaddrinfo
    for res in _socket.getaddrinfo(host, port, family, type, proto, flags):
socket.gaierror: [Errno -3] Temporary failure in name resolution
asyncio - ERROR - Task exception was never retrieved
future: <Task finished name='Task-5061' coro=<TCPConnector._resolve_host() done, defined at /home/diego-moraes/.local/lib/python3.8/site-packages/aiohttp/connector.py:774> exception=gaierror(-3, 'Temporary failure in name resolution')>
Traceback (most recent call last):
  File "/home/diego-moraes/.local/lib/python3.8/site-packages/aiohttp/connector.py", line 829, in _resolve_host
    addrs = await \
  File "/home/diego-moraes/.local/lib/python3.8/site-packages/aiohttp/resolver.py", line 29, in resolve
    infos = await self._loop.getaddrinfo(
  File "/usr/lib/python3.8/asyncio/base_events.py", line 825, in getaddrinfo
    return await self.run_in_executor(
  File "/usr/lib/python3.8/concurrent/futures/thread.py", line 57, in run
    result = self.fn(*self.args, **self.kwargs)
  File "/usr/lib/python3.8/socket.py", line 918, in getaddrinfo
    for res in _socket.getaddrinfo(host, port, family, type, proto, flags):
socket.gaierror: [Errno -3] Temporary failure in name resolution
asyncio - ERROR - Task exception was never retrieved
future: <Task finished name='Task-5166' coro=<TCPConnector._resolve_host() done, defined at /home/diego-moraes/.local/lib/python3.8/site-packages/aiohttp/connector.py:774> exception=gaierror(-3, 'Temporary failure in name resolution')>
Traceback (most recent call last):
  File "/home/diego-moraes/.local/lib/python3.8/site-packages/aiohttp/connector.py", line 815, in _resolve_host
    await event.wait()
  File "/home/diego-moraes/.local/lib/python3.8/site-packages/aiohttp/locks.py", line 37, in wait
    raise self._exc
  File "/home/diego-moraes/.local/lib/python3.8/site-packages/aiohttp/connector.py", line 829, in _resolve_host
    addrs = await \
  File "/home/diego-moraes/.local/lib/python3.8/site-packages/aiohttp/resolver.py", line 29, in resolve
    infos = await self._loop.getaddrinfo(
  File "/usr/lib/python3.8/asyncio/base_events.py", line 825, in getaddrinfo
    return await self.run_in_executor(
  File "/usr/lib/python3.8/concurrent/futures/thread.py", line 57, in run
    result = self.fn(*self.args, **self.kwargs)
  File "/usr/lib/python3.8/socket.py", line 918, in getaddrinfo
    for res in _socket.getaddrinfo(host, port, family, type, proto, flags):
socket.gaierror: [Errno -3] Temporary failure in name resolution
asyncio - ERROR - Task exception was never retrieved
future: <Task finished name='Task-5083' coro=<TCPConnector._resolve_host() done, defined at /home/diego-moraes/.local/lib/python3.8/site-packages/aiohttp/connector.py:774> exception=gaierror(-2, 'Name or service not known')>
Traceback (most recent call last):
  File "/home/diego-moraes/.local/lib/python3.8/site-packages/aiohttp/connector.py", line 829, in _resolve_host
    addrs = await \
  File "/home/diego-moraes/.local/lib/python3.8/site-packages/aiohttp/resolver.py", line 29, in resolve
    infos = await self._loop.getaddrinfo(
  File "/usr/lib/python3.8/asyncio/base_events.py", line 825, in getaddrinfo
    return await self.run_in_executor(
  File "/usr/lib/python3.8/concurrent/futures/thread.py", line 57, in run
    result = self.fn(*self.args, **self.kwargs)
  File "/usr/lib/python3.8/socket.py", line 918, in getaddrinfo
    for res in _socket.getaddrinfo(host, port, family, type, proto, flags):
socket.gaierror: [Errno -2] Name or service not known
asyncio - ERROR - Task exception was never retrieved
future: <Task finished name='Task-5076' coro=<TCPConnector._resolve_host() done, defined at /home/diego-moraes/.local/lib/python3.8/site-packages/aiohttp/connector.py:774> exception=gaierror(-2, 'Name or service not known')>
Traceback (most recent call last):
  File "/home/diego-moraes/.local/lib/python3.8/site-packages/aiohttp/connector.py", line 829, in _resolve_host
    addrs = await \
  File "/home/diego-moraes/.local/lib/python3.8/site-packages/aiohttp/resolver.py", line 29, in resolve
    infos = await self._loop.getaddrinfo(
  File "/usr/lib/python3.8/asyncio/base_events.py", line 825, in getaddrinfo
    return await self.run_in_executor(
  File "/usr/lib/python3.8/concurrent/futures/thread.py", line 57, in run
    result = self.fn(*self.args, **self.kwargs)
  File "/usr/lib/python3.8/socket.py", line 918, in getaddrinfo
    for res in _socket.getaddrinfo(host, port, family, type, proto, flags):
socket.gaierror: [Errno -2] Name or service not known
asyncio - ERROR - Task exception was never retrieved
future: <Task finished name='Task-5303' coro=<TCPConnector._resolve_host() done, defined at /home/diego-moraes/.local/lib/python3.8/site-packages/aiohttp/connector.py:774> exception=gaierror(-2, 'Name or service not known')>
Traceback (most recent call last):
  File "/home/diego-moraes/.local/lib/python3.8/site-packages/aiohttp/connector.py", line 815, in _resolve_host
    await event.wait()
  File "/home/diego-moraes/.local/lib/python3.8/site-packages/aiohttp/locks.py", line 37, in wait
    raise self._exc
  File "/home/diego-moraes/.local/lib/python3.8/site-packages/aiohttp/connector.py", line 829, in _resolve_host
    addrs = await \
  File "/home/diego-moraes/.local/lib/python3.8/site-packages/aiohttp/resolver.py", line 29, in resolve
    infos = await self._loop.getaddrinfo(
  File "/usr/lib/python3.8/asyncio/base_events.py", line 825, in getaddrinfo
    return await self.run_in_executor(
  File "/usr/lib/python3.8/concurrent/futures/thread.py", line 57, in run
    result = self.fn(*self.args, **self.kwargs)
  File "/usr/lib/python3.8/socket.py", line 918, in getaddrinfo
    for res in _socket.getaddrinfo(host, port, family, type, proto, flags):
socket.gaierror: [Errno -2] Name or service not known
asyncio - ERROR - Task exception was never retrieved
future: <Task finished name='Task-5082' coro=<TCPConnector._resolve_host() done, defined at /home/diego-moraes/.local/lib/python3.8/site-packages/aiohttp/connector.py:774> exception=gaierror(-3, 'Temporary failure in name resolution')>
Traceback (most recent call last):
  File "/home/diego-moraes/.local/lib/python3.8/site-packages/aiohttp/connector.py", line 829, in _resolve_host
    addrs = await \
  File "/home/diego-moraes/.local/lib/python3.8/site-packages/aiohttp/resolver.py", line 29, in resolve
    infos = await self._loop.getaddrinfo(
  File "/usr/lib/python3.8/asyncio/base_events.py", line 825, in getaddrinfo
    return await self.run_in_executor(
  File "/usr/lib/python3.8/concurrent/futures/thread.py", line 57, in run
    result = self.fn(*self.args, **self.kwargs)
  File "/usr/lib/python3.8/socket.py", line 918, in getaddrinfo
    for res in _socket.getaddrinfo(host, port, family, type, proto, flags):
socket.gaierror: [Errno -3] Temporary failure in name resolution
asyncio - ERROR - Task exception was never retrieved
future: <Task finished name='Task-5081' coro=<TCPConnector._resolve_host() done, defined at /home/diego-moraes/.local/lib/python3.8/site-packages/aiohttp/connector.py:774> exception=gaierror(-3, 'Temporary failure in name resolution')>
Traceback (most recent call last):
  File "/home/diego-moraes/.local/lib/python3.8/site-packages/aiohttp/connector.py", line 829, in _resolve_host
    addrs = await \
  File "/home/diego-moraes/.local/lib/python3.8/site-packages/aiohttp/resolver.py", line 29, in resolve
    infos = await self._loop.getaddrinfo(
  File "/usr/lib/python3.8/asyncio/base_events.py", line 825, in getaddrinfo
    return await self.run_in_executor(
  File "/usr/lib/python3.8/concurrent/futures/thread.py", line 57, in run
    result = self.fn(*self.args, **self.kwargs)
  File "/usr/lib/python3.8/socket.py", line 918, in getaddrinfo
    for res in _socket.getaddrinfo(host, port, family, type, proto, flags):
socket.gaierror: [Errno -3] Temporary failure in name resolution
asyncio - ERROR - Task exception was never retrieved
future: <Task finished name='Task-5079' coro=<TCPConnector._resolve_host() done, defined at /home/diego-moraes/.local/lib/python3.8/site-packages/aiohttp/connector.py:774> exception=gaierror(-3, 'Temporary failure in name resolution')>
Traceback (most recent call last):
  File "/home/diego-moraes/.local/lib/python3.8/site-packages/aiohttp/connector.py", line 829, in _resolve_host
    addrs = await \
  File "/home/diego-moraes/.local/lib/python3.8/site-packages/aiohttp/resolver.py", line 29, in resolve
    infos = await self._loop.getaddrinfo(
  File "/usr/lib/python3.8/asyncio/base_events.py", line 825, in getaddrinfo
    return await self.run_in_executor(
  File "/usr/lib/python3.8/concurrent/futures/thread.py", line 57, in run
    result = self.fn(*self.args, **self.kwargs)
  File "/usr/lib/python3.8/socket.py", line 918, in getaddrinfo
    for res in _socket.getaddrinfo(host, port, family, type, proto, flags):
socket.gaierror: [Errno -3] Temporary failure in name resolution
asyncio - ERROR - Task exception was never retrieved
future: <Task finished name='Task-5078' coro=<TCPConnector._resolve_host() done, defined at /home/diego-moraes/.local/lib/python3.8/site-packages/aiohttp/connector.py:774> exception=gaierror(-3, 'Temporary failure in name resolution')>
Traceback (most recent call last):
  File "/home/diego-moraes/.local/lib/python3.8/site-packages/aiohttp/connector.py", line 829, in _resolve_host
    addrs = await \
  File "/home/diego-moraes/.local/lib/python3.8/site-packages/aiohttp/resolver.py", line 29, in resolve
    infos = await self._loop.getaddrinfo(
  File "/usr/lib/python3.8/asyncio/base_events.py", line 825, in getaddrinfo
    return await self.run_in_executor(
  File "/usr/lib/python3.8/concurrent/futures/thread.py", line 57, in run
    result = self.fn(*self.args, **self.kwargs)
  File "/usr/lib/python3.8/socket.py", line 918, in getaddrinfo
    for res in _socket.getaddrinfo(host, port, family, type, proto, flags):
socket.gaierror: [Errno -3] Temporary failure in name resolution
asyncio - ERROR - Task exception was never retrieved
future: <Task finished name='Task-5080' coro=<TCPConnector._resolve_host() done, defined at /home/diego-moraes/.local/lib/python3.8/site-packages/aiohttp/connector.py:774> exception=gaierror(-3, 'Temporary failure in name resolution')>
Traceback (most recent call last):
  File "/home/diego-moraes/.local/lib/python3.8/site-packages/aiohttp/connector.py", line 829, in _resolve_host
    addrs = await \
  File "/home/diego-moraes/.local/lib/python3.8/site-packages/aiohttp/resolver.py", line 29, in resolve
    infos = await self._loop.getaddrinfo(
  File "/usr/lib/python3.8/asyncio/base_events.py", line 825, in getaddrinfo
    return await self.run_in_executor(
  File "/usr/lib/python3.8/concurrent/futures/thread.py", line 57, in run
    result = self.fn(*self.args, **self.kwargs)
  File "/usr/lib/python3.8/socket.py", line 918, in getaddrinfo
    for res in _socket.getaddrinfo(host, port, family, type, proto, flags):
socket.gaierror: [Errno -3] Temporary failure in name resolution
asyncio - ERROR - Task exception was never retrieved
future: <Task finished name='Task-5096' coro=<TCPConnector._resolve_host() done, defined at /home/diego-moraes/.local/lib/python3.8/site-packages/aiohttp/connector.py:774> exception=gaierror(-2, 'Name or service not known')>
Traceback (most recent call last):
  File "/home/diego-moraes/.local/lib/python3.8/site-packages/aiohttp/connector.py", line 829, in _resolve_host
    addrs = await \
  File "/home/diego-moraes/.local/lib/python3.8/site-packages/aiohttp/resolver.py", line 29, in resolve
    infos = await self._loop.getaddrinfo(
  File "/usr/lib/python3.8/asyncio/base_events.py", line 825, in getaddrinfo
    return await self.run_in_executor(
  File "/usr/lib/python3.8/concurrent/futures/thread.py", line 57, in run
    result = self.fn(*self.args, **self.kwargs)
  File "/usr/lib/python3.8/socket.py", line 918, in getaddrinfo
    for res in _socket.getaddrinfo(host, port, family, type, proto, flags):
socket.gaierror: [Errno -2] Name or service not known
asyncio - ERROR - Task exception was never retrieved
future: <Task finished name='Task-5094' coro=<TCPConnector._resolve_host() done, defined at /home/diego-moraes/.local/lib/python3.8/site-packages/aiohttp/connector.py:774> exception=gaierror(-2, 'Name or service not known')>
Traceback (most recent call last):
  File "/home/diego-moraes/.local/lib/python3.8/site-packages/aiohttp/connector.py", line 829, in _resolve_host
    addrs = await \
  File "/home/diego-moraes/.local/lib/python3.8/site-packages/aiohttp/resolver.py", line 29, in resolve
    infos = await self._loop.getaddrinfo(
  File "/usr/lib/python3.8/asyncio/base_events.py", line 825, in getaddrinfo
    return await self.run_in_executor(
  File "/usr/lib/python3.8/concurrent/futures/thread.py", line 57, in run
    result = self.fn(*self.args, **self.kwargs)
  File "/usr/lib/python3.8/socket.py", line 918, in getaddrinfo
    for res in _socket.getaddrinfo(host, port, family, type, proto, flags):
socket.gaierror: [Errno -2] Name or service not known
asyncio - ERROR - Task exception was never retrieved
future: <Task finished name='Task-5085' coro=<TCPConnector._resolve_host() done, defined at /home/diego-moraes/.local/lib/python3.8/site-packages/aiohttp/connector.py:774> exception=gaierror(-2, 'Name or service not known')>
Traceback (most recent call last):
  File "/home/diego-moraes/.local/lib/python3.8/site-packages/aiohttp/connector.py", line 829, in _resolve_host
    addrs = await \
  File "/home/diego-moraes/.local/lib/python3.8/site-packages/aiohttp/resolver.py", line 29, in resolve
    infos = await self._loop.getaddrinfo(
  File "/usr/lib/python3.8/asyncio/base_events.py", line 825, in getaddrinfo
    return await self.run_in_executor(
  File "/usr/lib/python3.8/concurrent/futures/thread.py", line 57, in run
    result = self.fn(*self.args, **self.kwargs)
  File "/usr/lib/python3.8/socket.py", line 918, in getaddrinfo
    for res in _socket.getaddrinfo(host, port, family, type, proto, flags):
socket.gaierror: [Errno -2] Name or service not known
asyncio - ERROR - Task exception was never retrieved
future: <Task finished name='Task-5251' coro=<TCPConnector._resolve_host() done, defined at /home/diego-moraes/.local/lib/python3.8/site-packages/aiohttp/connector.py:774> exception=gaierror(-2, 'Name or service not known')>
Traceback (most recent call last):
  File "/home/diego-moraes/.local/lib/python3.8/site-packages/aiohttp/connector.py", line 815, in _resolve_host
    await event.wait()
  File "/home/diego-moraes/.local/lib/python3.8/site-packages/aiohttp/locks.py", line 37, in wait
    raise self._exc
  File "/home/diego-moraes/.local/lib/python3.8/site-packages/aiohttp/connector.py", line 829, in _resolve_host
    addrs = await \
  File "/home/diego-moraes/.local/lib/python3.8/site-packages/aiohttp/resolver.py", line 29, in resolve
    infos = await self._loop.getaddrinfo(
  File "/usr/lib/python3.8/asyncio/base_events.py", line 825, in getaddrinfo
    return await self.run_in_executor(
  File "/usr/lib/python3.8/concurrent/futures/thread.py", line 57, in run
    result = self.fn(*self.args, **self.kwargs)
  File "/usr/lib/python3.8/socket.py", line 918, in getaddrinfo
    for res in _socket.getaddrinfo(host, port, family, type, proto, flags):
socket.gaierror: [Errno -2] Name or service not known
asyncio - ERROR - Task exception was never retrieved
future: <Task finished name='Task-5064' coro=<TCPConnector._resolve_host() done, defined at /home/diego-moraes/.local/lib/python3.8/site-packages/aiohttp/connector.py:774> exception=gaierror(-3, 'Temporary failure in name resolution')>
Traceback (most recent call last):
  File "/home/diego-moraes/.local/lib/python3.8/site-packages/aiohttp/connector.py", line 829, in _resolve_host
    addrs = await \
  File "/home/diego-moraes/.local/lib/python3.8/site-packages/aiohttp/resolver.py", line 29, in resolve
    infos = await self._loop.getaddrinfo(
  File "/usr/lib/python3.8/asyncio/base_events.py", line 825, in getaddrinfo
    return await self.run_in_executor(
  File "/usr/lib/python3.8/concurrent/futures/thread.py", line 57, in run
    result = self.fn(*self.args, **self.kwargs)
  File "/usr/lib/python3.8/socket.py", line 918, in getaddrinfo
    for res in _socket.getaddrinfo(host, port, family, type, proto, flags):
socket.gaierror: [Errno -3] Temporary failure in name resolution
